Val True labels:  [0, 0, 1, 0, 0, 0, 0, 1, 0, 0, 1, 1, 0, 0, 1, 0, 1, 0, 0, 1, 0, 0, 1, 0, 1, 0, 0, 0, 0, 1, 1, 1, 0, 0, 0, 1, 0, 0, 1, 1, 0, 0, 0, 1, 0, 0, 0, 1, 0, 0, 1, 0, 0, 1, 0, 0, 1, 0, 0, 0, 1, 0, 0, 1, 0, 1, 0, 1, 0, 1, 0, 1, 0, 0, 1, 0, 0]
Val Predicted labels:  [1, 1, 1, 1, 1, 1, 1, 1, 1, 1, 1, 1, 1, 1, 1, 1, 1, 1, 1, 1, 1, 1, 1, 1, 1, 1, 0, 1, 1, 1, 1, 1, 1, 1, 1, 1, 1, 1, 1, 0, 1, 0, 1, 1, 1, 1, 1, 1, 1, 1, 1, 1, 1, 1, 1, 1, 1, 1, 1, 1, 1, 1, 1, 1, 1, 1, 1, 1, 1, 1, 1, 1, 1, 1, 1, 1, 1]
Traceback (most recent call last):
  File "/Users/volodimir/anaconda3/envs/Global/lib/python3.11/site-packages/wandb/sdk/wandb_config.py", line 162, in __getattr__
    return self.__getitem__(key)
           ^^^^^^^^^^^^^^^^^^^^^
  File "/Users/volodimir/anaconda3/envs/Global/lib/python3.11/site-packages/wandb/sdk/wandb_config.py", line 130, in __getitem__
    return self._items[key]
           ~~~~~~~~~~~^^^^^
KeyError: 'save_weights'
The above exception was the direct cause of the following exception:
Traceback (most recent call last):
  File "/Users/volodimir/Downloads/Bachelor/CrossValidation/training.py", line 136, in <module>
    train()
  File "/Users/volodimir/Downloads/Bachelor/CrossValidation/training.py", line 72, in train
    if run.config.save_weights:
       ^^^^^^^^^^^^^^^^^^^^^^^
  File "/Users/volodimir/anaconda3/envs/Global/lib/python3.11/site-packages/wandb/sdk/wandb_config.py", line 164, in __getattr__
    raise AttributeError(
AttributeError: <class 'wandb.sdk.wandb_config.Config'> object has no attribute 'save_weights'