2024-03-17 20:14:22,431 INFO    MainThread:7117 [wandb_setup.py:_flush():76] Current SDK version is 0.16.3
2024-03-17 20:14:22,432 INFO    MainThread:7117 [wandb_setup.py:_flush():76] Configure stats pid to 7117
2024-03-17 20:14:22,432 INFO    MainThread:7117 [wandb_setup.py:_flush():76] Loading settings from /Users/volodimir/.config/wandb/settings
2024-03-17 20:14:22,432 INFO    MainThread:7117 [wandb_setup.py:_flush():76] Loading settings from /Users/volodimir/Downloads/Bachelor/CrossValidation/wandb/settings
2024-03-17 20:14:22,432 WARNING MainThread:7117 [wandb_setup.py:_flush():76] Unknown environment variable: WANDB_SERVICE
2024-03-17 20:14:22,432 INFO    MainThread:7117 [wandb_setup.py:_flush():76] Loading settings from environment variables: {'entity': 'daswoldemar', 'project': 'bachelor-test', 'sweep_id': 'zu1vf366', 'root_dir': '/Users/volodimir/Downloads/Bachelor/CrossValidation', 'run_id': '5p21sa3f', 'sweep_param_path': '/Users/volodimir/Downloads/Bachelor/CrossValidation/wandb/sweep-zu1vf366/config-5p21sa3f.yaml'}
2024-03-17 20:14:22,432 INFO    MainThread:7117 [wandb_setup.py:_flush():76] Applying setup settings: {'_disable_service': False}
2024-03-17 20:14:22,433 INFO    MainThread:7117 [wandb_setup.py:_flush():76] Inferring run settings from compute environment: {'program_relpath': 'CrossValidation/training.py', 'program_abspath': '/Users/volodimir/Downloads/Bachelor/CrossValidation/training.py', 'program': '/Users/volodimir/Downloads/Bachelor/CrossValidation/training.py'}
2024-03-17 20:14:22,433 INFO    MainThread:7117 [wandb_init.py:_log_setup():526] Logging user logs to /Users/volodimir/Downloads/Bachelor/CrossValidation/wandb/run-20240317_201422-5p21sa3f/logs/debug.log
2024-03-17 20:14:22,433 INFO    MainThread:7117 [wandb_init.py:_log_setup():527] Logging internal logs to /Users/volodimir/Downloads/Bachelor/CrossValidation/wandb/run-20240317_201422-5p21sa3f/logs/debug-internal.log
2024-03-17 20:14:22,433 INFO    MainThread:7117 [wandb_init.py:init():566] calling init triggers
2024-03-17 20:14:22,433 INFO    MainThread:7117 [wandb_init.py:init():573] wandb.init called with sweep_config: {'batch_size': 64, 'fold': 'fold_0', 'transform': 'none'}
config: {'program': 'training.py', 'name': 'with_cross_val_size_600_500', 'method': 'grid', 'metric': {'goal': 'minimize', 'name': 'test_loss'}, 'parameters': {'transform': {'values': ['none', 'random_erasing_delete', 'random_erasing_random', 'random_crop', 'random_horizontal_flip', 'random_vertical_flip', 'random_rotation', 'color_jitter', 'random_noise(0.4, 0.5)', 'random_noise(0, 0.1)']}, 'fold': {'values': ['fold_0', 'fold_1', 'fold_2', 'fold_3', 'fold_4']}, 'batch_size': {'values': [64]}}, 'image_size': {'height': 600, 'width': 600}, 'folds_path': 'metadata_folds/kkui-lung-bline-lumify:latest/video', 'optimizer': 'adam', 'learning_rate': 1e-05, 'criterion': 'cross-entropy', 'img_dir': '/Volumes/LaCie/Macbook/Bachelor/CrossValidation/', 'fc_layer_size': 512, 'number_of_classes': 2, 'patience': 5, 'epochs': 30, 'save_weights': True, 'comment': 'trying with small lr and eval on training part, transform as on resnet paper'}
2024-03-17 20:14:22,433 INFO    MainThread:7117 [wandb_init.py:init():616] starting backend
2024-03-17 20:14:22,433 INFO    MainThread:7117 [wandb_init.py:init():620] setting up manager
2024-03-17 20:14:22,439 INFO    MainThread:7117 [backend.py:_multiprocessing_setup():105] multiprocessing start_methods=spawn,fork,forkserver, using: spawn
2024-03-17 20:14:22,441 INFO    MainThread:7117 [wandb_init.py:init():628] backend started and connected
2024-03-17 20:14:22,445 INFO    MainThread:7117 [wandb_run.py:_config_callback():1343] config_cb None None {'batch_size': 64, 'fold': 'fold_0', 'transform': 'none'}
2024-03-17 20:14:22,446 INFO    MainThread:7117 [wandb_init.py:init():720] updated telemetry
2024-03-17 20:14:22,455 INFO    MainThread:7117 [wandb_init.py:init():753] communicating run to backend with 90.0 second timeout
2024-03-17 20:14:27,154 INFO    MainThread:7117 [wandb_run.py:_on_init():2262] communicating current version
2024-03-17 20:14:27,262 INFO    MainThread:7117 [wandb_run.py:_on_init():2271] got version response upgrade_message: "wandb version 0.16.4 is available!  To upgrade, please run:\n $ pip install wandb --upgrade"

2024-03-17 20:14:27,262 INFO    MainThread:7117 [wandb_init.py:init():804] starting run threads in backend
2024-03-17 20:14:29,610 INFO    MainThread:7117 [wandb_run.py:_console_start():2241] atexit reg
2024-03-17 20:14:29,610 INFO    MainThread:7117 [wandb_run.py:_redirect():2096] redirect: wrap_raw
2024-03-17 20:14:29,610 INFO    MainThread:7117 [wandb_run.py:_redirect():2161] Wrapping output streams.
2024-03-17 20:14:29,610 INFO    MainThread:7117 [wandb_run.py:_redirect():2186] Redirects installed.
2024-03-17 20:14:29,611 INFO    MainThread:7117 [wandb_init.py:init():847] run started, returning control to user process
2024-03-17 20:33:08,524 INFO    MainThread:7117 [retry.py:__call__():172] Retry attempt failed:
Traceback (most recent call last):
  File "/Users/volodimir/anaconda3/envs/Global/lib/python3.11/site-packages/urllib3/connection.py", line 203, in _new_conn
    sock = connection.create_connection(
           ^^^^^^^^^^^^^^^^^^^^^^^^^^^^^
  File "/Users/volodimir/anaconda3/envs/Global/lib/python3.11/site-packages/urllib3/util/connection.py", line 60, in create_connection
    for res in socket.getaddrinfo(host, port, family, socket.SOCK_STREAM):
               ^^^^^^^^^^^^^^^^^^^^^^^^^^^^^^^^^^^^^^^^^^^^^^^^^^^^^^^^^^
  File "/Users/volodimir/anaconda3/envs/Global/lib/python3.11/socket.py", line 961, in getaddrinfo
    for res in _socket.getaddrinfo(host, port, family, type, proto, flags):
               ^^^^^^^^^^^^^^^^^^^^^^^^^^^^^^^^^^^^^^^^^^^^^^^^^^^^^^^^^^^
socket.gaierror: [Errno 8] nodename nor servname provided, or not known

The above exception was the direct cause of the following exception:

Traceback (most recent call last):
  File "/Users/volodimir/anaconda3/envs/Global/lib/python3.11/site-packages/urllib3/connectionpool.py", line 790, in urlopen
    response = self._make_request(
               ^^^^^^^^^^^^^^^^^^^
  File "/Users/volodimir/anaconda3/envs/Global/lib/python3.11/site-packages/urllib3/connectionpool.py", line 491, in _make_request
    raise new_e
  File "/Users/volodimir/anaconda3/envs/Global/lib/python3.11/site-packages/urllib3/connectionpool.py", line 467, in _make_request
    self._validate_conn(conn)
  File "/Users/volodimir/anaconda3/envs/Global/lib/python3.11/site-packages/urllib3/connectionpool.py", line 1096, in _validate_conn
    conn.connect()
  File "/Users/volodimir/anaconda3/envs/Global/lib/python3.11/site-packages/urllib3/connection.py", line 611, in connect
    self.sock = sock = self._new_conn()
                       ^^^^^^^^^^^^^^^^
  File "/Users/volodimir/anaconda3/envs/Global/lib/python3.11/site-packages/urllib3/connection.py", line 210, in _new_conn
    raise NameResolutionError(self.host, self, e) from e
urllib3.exceptions.NameResolutionError: <urllib3.connection.HTTPSConnection object at 0x385615ed0>: Failed to resolve 'api.wandb.ai' ([Errno 8] nodename nor servname provided, or not known)

The above exception was the direct cause of the following exception:

Traceback (most recent call last):
  File "/Users/volodimir/anaconda3/envs/Global/lib/python3.11/site-packages/requests/adapters.py", line 486, in send
    resp = conn.urlopen(
           ^^^^^^^^^^^^^
  File "/Users/volodimir/anaconda3/envs/Global/lib/python3.11/site-packages/urllib3/connectionpool.py", line 844, in urlopen
    retries = retries.increment(
              ^^^^^^^^^^^^^^^^^^
  File "/Users/volodimir/anaconda3/envs/Global/lib/python3.11/site-packages/urllib3/util/retry.py", line 515, in increment
    raise MaxRetryError(_pool, url, reason) from reason  # type: ignore[arg-type]
    ^^^^^^^^^^^^^^^^^^^^^^^^^^^^^^^^^^^^^^^^^^^^^^^^^^^
urllib3.exceptions.MaxRetryError: HTTPSConnectionPool(host='api.wandb.ai', port=443): Max retries exceeded with url: /graphql (Caused by NameResolutionError("<urllib3.connection.HTTPSConnection object at 0x385615ed0>: Failed to resolve 'api.wandb.ai' ([Errno 8] nodename nor servname provided, or not known)"))

During handling of the above exception, another exception occurred:

Traceback (most recent call last):
  File "/Users/volodimir/anaconda3/envs/Global/lib/python3.11/site-packages/wandb/sdk/lib/retry.py", line 131, in __call__
    result = self._call_fn(*args, **kwargs)
             ^^^^^^^^^^^^^^^^^^^^^^^^^^^^^^
  File "/Users/volodimir/anaconda3/envs/Global/lib/python3.11/site-packages/wandb/sdk/internal/internal_api.py", line 369, in execute
    return self.client.execute(*args, **kwargs)  # type: ignore
           ^^^^^^^^^^^^^^^^^^^^^^^^^^^^^^^^^^^^
  File "/Users/volodimir/anaconda3/envs/Global/lib/python3.11/site-packages/wandb/vendor/gql-0.2.0/wandb_gql/client.py", line 52, in execute
    result = self._get_result(document, *args, **kwargs)
             ^^^^^^^^^^^^^^^^^^^^^^^^^^^^^^^^^^^^^^^^^^^
  File "/Users/volodimir/anaconda3/envs/Global/lib/python3.11/site-packages/wandb/vendor/gql-0.2.0/wandb_gql/client.py", line 60, in _get_result
    return self.transport.execute(document, *args, **kwargs)
           ^^^^^^^^^^^^^^^^^^^^^^^^^^^^^^^^^^^^^^^^^^^^^^^^^
  File "/Users/volodimir/anaconda3/envs/Global/lib/python3.11/site-packages/wandb/sdk/lib/gql_request.py", line 58, in execute
    request = self.session.post(self.url, **post_args)
              ^^^^^^^^^^^^^^^^^^^^^^^^^^^^^^^^^^^^^^^^
  File "/Users/volodimir/anaconda3/envs/Global/lib/python3.11/site-packages/requests/sessions.py", line 637, in post
    return self.request("POST", url, data=data, json=json, **kwargs)
           ^^^^^^^^^^^^^^^^^^^^^^^^^^^^^^^^^^^^^^^^^^^^^^^^^^^^^^^^^
  File "/Users/volodimir/anaconda3/envs/Global/lib/python3.11/site-packages/requests/sessions.py", line 589, in request
    resp = self.send(prep, **send_kwargs)
           ^^^^^^^^^^^^^^^^^^^^^^^^^^^^^^
  File "/Users/volodimir/anaconda3/envs/Global/lib/python3.11/site-packages/requests/sessions.py", line 703, in send
    r = adapter.send(request, **kwargs)
        ^^^^^^^^^^^^^^^^^^^^^^^^^^^^^^^
  File "/Users/volodimir/anaconda3/envs/Global/lib/python3.11/site-packages/requests/adapters.py", line 519, in send
    raise ConnectionError(e, request=request)
requests.exceptions.ConnectionError: HTTPSConnectionPool(host='api.wandb.ai', port=443): Max retries exceeded with url: /graphql (Caused by NameResolutionError("<urllib3.connection.HTTPSConnection object at 0x385615ed0>: Failed to resolve 'api.wandb.ai' ([Errno 8] nodename nor servname provided, or not known)"))
2024-03-17 20:43:52,376 INFO    MainThread:7117 [wandb_run.py:_config_callback():1343] config_cb ('_wandb', 'visualize', 'confusion_matrix') {'panel_type': 'Vega2', 'panel_config': {'panelDefId': 'wandb/confusion_matrix/v1', 'fieldSettings': {'Actual': 'Actual', 'Predicted': 'Predicted', 'nPredictions': 'nPredictions'}, 'stringSettings': {'title': ''}, 'transform': {'name': 'tableWithLeafColNames'}, 'userQuery': {'queryFields': [{'name': 'runSets', 'args': [{'name': 'runSets', 'value': '${runSets}'}], 'fields': [{'name': 'id', 'fields': []}, {'name': 'name', 'fields': []}, {'name': '_defaultColorIndex', 'fields': []}, {'name': 'summaryTable', 'args': [{'name': 'tableKey', 'value': 'confusion_matrix_table'}], 'fields': []}]}]}}} None
