{'mode': 'r', 'batch_size': 64, 'fold': 'fold_2', 'transform': 'random_erasing_delete'}
{'mode': 'r', 'batch_size': 64, 'fold': 'fold_2', 'transform': 'random_erasing_delete'}
Traceback (most recent call last):
  File "/Users/volodimir/anaconda3/envs/Global/lib/python3.11/site-packages/wandb/sdk/wandb_config.py", line 162, in __getattr__
    return self.__getitem__(key)
           ^^^^^^^^^^^^^^^^^^^^^
  File "/Users/volodimir/anaconda3/envs/Global/lib/python3.11/site-packages/wandb/sdk/wandb_config.py", line 130, in __getitem__
    return self._items[key]
           ~~~~~~~~~~~^^^^^
KeyError: 'folds_path'
The above exception was the direct cause of the following exception:
Traceback (most recent call last):
  File "/Users/volodimir/Downloads/Bachelor/CrossValidation/training.py", line 91, in <module>
    train()
  File "/Users/volodimir/Downloads/Bachelor/CrossValidation/training.py", line 24, in train
    fold_json_path = str(join(run.config.folds_path, run.config.fold + ".json"))
                              ^^^^^^^^^^^^^^^^^^^^^
  File "/Users/volodimir/anaconda3/envs/Global/lib/python3.11/site-packages/wandb/sdk/wandb_config.py", line 164, in __getattr__
    raise AttributeError(
AttributeError: <class 'wandb.sdk.wandb_config.Config'> object has no attribute 'folds_path'